#params: 1199882
> /content/drive/Othercomputers/My MacBook Pro (corp)/transformers/main.py(47)train()
-> print(f'train_set.shape: {train_set.shape}')
PYDEV DEBUGGER WARNING:
sys.settrace() should not be used when the debugger is being used.
This may cause the debugger to stop working correctly.
If this is needed, please check:
http://pydev.blogspot.com/2007/06/why-cant-pydev-debugger-work-with.html
to see how to restore the debug tracing back correctly.
Call Location:
  File "/usr/lib/python3.8/bdb.py", line 334, in set_trace
    sys.settrace(self.trace_dispatch)
array([[[0, 0, 0, ..., 0, 0, 0],
        [0, 0, 0, ..., 0, 0, 0],
        [0, 0, 0, ..., 0, 0, 0],
        ...,
        [0, 0, 0, ..., 0, 0, 0],
        [0, 0, 0, ..., 0, 0, 0],
        [0, 0, 0, ..., 0, 0, 0]],
       [[0, 0, 0, ..., 0, 0, 0],
        [0, 0, 0, ..., 0, 0, 0],
        [0, 0, 0, ..., 0, 0, 0],
        ...,
        [0, 0, 0, ..., 0, 0, 0],
        [0, 0, 0, ..., 0, 0, 0],
        [0, 0, 0, ..., 0, 0, 0]],
       [[0, 0, 0, ..., 0, 0, 0],
        [0, 0, 0, ..., 0, 0, 0],
        [0, 0, 0, ..., 0, 0, 0],
        ...,
        [0, 0, 0, ..., 0, 0, 0],
        [0, 0, 0, ..., 0, 0, 0],
        [0, 0, 0, ..., 0, 0, 0]],
       ...,
       [[0, 0, 0, ..., 0, 0, 0],
        [0, 0, 0, ..., 0, 0, 0],
        [0, 0, 0, ..., 0, 0, 0],
        ...,
        [0, 0, 0, ..., 0, 0, 0],
        [0, 0, 0, ..., 0, 0, 0],
        [0, 0, 0, ..., 0, 0, 0]],
       [[0, 0, 0, ..., 0, 0, 0],
        [0, 0, 0, ..., 0, 0, 0],
        [0, 0, 0, ..., 0, 0, 0],
        ...,
        [0, 0, 0, ..., 0, 0, 0],
        [0, 0, 0, ..., 0, 0, 0],
        [0, 0, 0, ..., 0, 0, 0]],
       [[0, 0, 0, ..., 0, 0, 0],
        [0, 0, 0, ..., 0, 0, 0],
        [0, 0, 0, ..., 0, 0, 0],
        ...,
        [0, 0, 0, ..., 0, 0, 0],
        [0, 0, 0, ..., 0, 0, 0],
        [0, 0, 0, ..., 0, 0, 0]]], dtype=uint8)
(60000, 28, 28)
train_set.shape: (60000, 28, 28)
PYDEV DEBUGGER WARNING:
sys.settrace() should not be used when the debugger is being used.
This may cause the debugger to stop working correctly.
If this is needed, please check:
http://pydev.blogspot.com/2007/06/why-cant-pydev-debugger-work-with.html
to see how to restore the debug tracing back correctly.
Call Location:
  File "/usr/lib/python3.8/bdb.py", line 345, in set_continue
    sys.settrace(None)
  0%|          | 0/600 [00:00<?, ?it/s]